# -*- Mode:Python; indent-tabs-mode:nil; tab-width:4 -*-
#
# Copyright (C) 2017 Canonical Ltd
#
# This program is free software: you can redistribute it and/or modify
# it under the terms of the GNU General Public License version 3 as
# published by the Free Software Foundation.
#
# This program is distributed in the hope that it will be useful,
# but WITHOUT ANY WARRANTY; without even the implied warranty of
# MERCHANTABILITY or FITNESS FOR A PARTICULAR PURPOSE.  See the
# GNU General Public License for more details.
#
# You should have received a copy of the GNU General Public License
# along with this program.  If not, see <http://www.gnu.org/licenses/>.

import sys

from snapcraft.cli._errors import exception_handler
import snapcraft.internal.errors

from unittest import mock

from snapcraft.tests import unit


class TestSnapcraftError(snapcraft.internal.errors.SnapcraftError):

    fmt = '{message}'

    def __init__(self, message):
        super().__init__(message=message)

    def get_exit_code(self):
        return 123


class ErrorsTestCase(unit.TestCase):

    def setUp(self):
        super().setUp()

        patcher = mock.patch('sys.exit')
        self.exit_mock = patcher.start()
        self.addCleanup(patcher.stop)

        patcher = mock.patch('snapcraft.cli._errors.echo.error')
        self.error_mock = patcher.start()
        self.addCleanup(patcher.stop)

        patcher = mock.patch('traceback.print_exception')
        self.print_exception_mock = patcher.start()
        self.addCleanup(patcher.stop)

    def call_handler(self, exception, debug):
        try:
            raise exception
        except Exception:
            exception_handler(*sys.exc_info(), debug=debug)

    def assert_exception_traceback_exit_1(self):
        self.error_mock.assert_not_called
        self.exit_mock.assert_called_once_with(1)
        self.print_exception_mock.assert_called_once_with(
            RuntimeError, mock.ANY, mock.ANY)

    def test_handler_traceback_non_snapcraft_exceptions_no_debug(self):
        try:
            self.call_handler(RuntimeError('not a SnapcraftError'), False)
        except Exception:
            self.fail('Exception unexpectedly raised')

        self.assert_exception_traceback_exit_1()

    def test_handler_traceback_non_snapcraft_exceptions_debug(self):
        try:
            self.call_handler(RuntimeError('not a SnapcraftError'), True)
        except Exception:
            self.fail('Exception unexpectedly raised')

        self.assert_exception_traceback_exit_1()

    def test_handler_catches_snapcraft_exceptions_no_debug(self):
        try:
            self.call_handler(TestSnapcraftError('is a SnapcraftError'), False)
        except Exception:
            self.fail('Exception unexpectedly raised')

        self.error_mock.assert_called_once_with('is a SnapcraftError')
        self.exit_mock.assert_called_once_with(123)
        self.print_exception_mock.assert_not_called

    def test_handler_traces_snapcraft_exceptions_with_debug(self):
        try:
            self.call_handler(TestSnapcraftError('is a SnapcraftError'), True)
        except Exception:
            self.fail('Exception unexpectedly raised')

        self.error_mock.assert_not_called
        self.exit_mock.assert_not_called
        self.print_exception_mock.assert_called_once_with(
            TestSnapcraftError, mock.ANY, mock.ANY)
